<?xml version="1.0"?>

<robot xmlns:xacro="http://ros.org/wiki/xacro">
  <xacro:macro name="wheel" params="suffix mass wheel_radius wheel_width
    *link_origin *joint_origin">
    <link name="link_${suffix}_wheel">
      <inertial>
        <mass value="${mass}"/>
        <xacro:insert_block name="link_origin"/>
        <inertia ixx="${(1/12)*mass*
          (3*wheel_radius*wheel_radius+wheel_width*wheel_width)}"
          ixy="0" ixz="0" iyy="${(1/12)*mass*
          (3*wheel_radius*wheel_radius+wheel_width*wheel_width)}"
          iyz="0" izz="${(1/2)*mass*wheel_radius*wheel_radius}"/>
      </inertial>
      <collision>
        <xacro:insert_block name="link_origin"/>
        <geometry>
          <cylinder length="${wheel_width}" radius="${wheel_radius}"/>
        </geometry>
      </collision>
      <visual>
        <xacro:insert_block name="link_origin"/>
        <geometry>
          <cylinder length="${wheel_width}" radius="${wheel_radius}"/>
        </geometry>
      </visual>
    </link>
    <joint name="${suffix}_wheel_joint" type="continuous">
      <xacro:insert_block name="joint_origin" />
      <child link="link_${suffix}_wheel"/>
      <parent link="base_link"/>
      <axis rpy="0 0 0" xyz="0 1 0"/>
      <limit effort="100" velocity="1"/>
    </joint>
  </xacro:macro>

  <xacro:macro name="link_macro">
    <link name="link_chassis">
      <!-- pose and inertial -->
      <pose>0 0 0.1 0 0 0</pose>
      <inertial>
        <mass value="5"/>
        <origin rpy="0 0 0" xyz="0 0 0.1"/>
        <inertia ixx="0.0395416666667" ixy="0" ixz="0" iyy="0.106208333333"
          iyz="0" izz="0.106208333333"/>
      </inertial>
      <!-- body -->
      <collision name="collision_chassis">
        <geometry>
          <box size="0.5 0.3 0.07"/>
        </geometry>
      </collision>
      <visual>
        <origin rpy="0 0 0" xyz="0 0 0"/>
        <geometry>
          <box size="0.5 0.3 0.07"/>
        </geometry>
      </visual>
    </link>
  </xacro:macro>

</robot>

